<body style=max-width:80ch;margin:auto>
<h1 class="entry-title" style="margin-bottom:15px;">What can I do if I want to throw a C++ exception from my InitOnce callback?</h1>  <!-- .entry-meta -->

<p>Suppose you want to use the <code>Init­Once­Execute­Once</code> function to perform one-time initialization, but your initialization function might throw a C++ exception. We know that this is not allowed because <a href="https://blogs.msdn.microsoft.com/oldnewthing/20120910-00/?p=6653">you don’t control all the frames the exception is being thrown across</a>, so what are your options? </p>
<p>The naïve solution is to catch the exception before it escapes your callback, and then rethrow it on the other side. </p>
<pre>
void Sample()
{
    struct State {
        std::exception_ptr p;
        // other members you want to access from the lambda
    } state;
    if (!InitOnceExecuteOnce(&amp;g_InitOnce,
          [](PINIT_ONCE InitOnce, void* Parameter, void** Context)
          -&gt; BOOL
          {
              auto s = reinterpret_cast&lt;State*&gt;(Parameter);
              try {
                  init_stuff();
                  return TRUE;
              } catch (std::exception&amp; e) {
                  s-&gt;p = std::current_exception();
                  return FALSE;
              }
          }, &amp;state, nullptr)) {
        // Failed due to exception.  Rethrow now that we are
        // safely outside the InitOnceExecuteOnce function.
        std::rethrow_exception(state.p);
    }
}
</pre>
<p>A less cumbersome solution is to use <a href="https://blogs.msdn.microsoft.com/oldnewthing/20161222-00/?p=94995">synchronous two-phase initialization</a>: </p>
<pre>
void Sample()
{
    void* result;
    BOOL pending;
    if (!InitOnceBeginInitialize(&amp;g_InitOnce, 0,
                                 &amp;pending, &amp;result)) {
        if (pending) {
            try {
                init_stuff();
            } catch (...) {
                InitOnceComplete(&amp;g_InitOnce,
                                 INIT_ONCE_INIT_FAILED, result);
                throw;
            }
            InitOnceComplete(&amp;g_InitOnce, 0, result);
        }
    }
}
</pre>
<p>Synchronous two-phase initialization performs the initialization inline rather than in a callback, which saves you the trouble of having to save the exception in one place and rethrow it in another place. You can just tell the InitOnce engine that initialization failed and then allow the exception to propagate. </p>
<p>You might decide to wrap this pattern inside an RAII type. </p>
<pre>
class InitOnceGuard
{
public:
    InitOnceGuard(PINIT_ONCE initOnce) :
        m_initOnce(initOnce),
        m_success(InitOnceBeginInitialize(initOnce, 0, &amp;m_pending, nullptr)),
        m_status(INIT_ONCE_INIT_FAILED)
    {
    }

    ~InitOnceGuard()
    {
        if (NeedInitialization()) InitOnceComplete(m_initOnce, m_status, nullptr);
    }

    InitOnceGuard(const InitOnceGuard&amp;) = delete;
    InitOnceGuard(InitOnceGuard&amp;&amp;) = delete;
    InitOnceGuard&amp; operator=(const InitOnceGuard&amp;) = delete;
    InitOnceGuard&amp; operator=(const InitOnceGuard&amp;&amp;) = delete;

    bool NeedInitialization() { return m_success &amp;&amp; m_pending; }

    // If you don't Complete, then the guard assumes that initialization failed.
    void Complete() { m_status = 0; }

private:
    PINIT_ONCE m_initOnce;
    bool m_success;
    bool m_pending;
    DWORD m_status;
}

void Sample()
{
    InitOnceGuard guard(&amp;g_InitOnce);
    if (guard.NeedInitialization()) {
        init_stuff();
        guard.Complete();
    }
}
</pre>
<p>If the <code>guard</code> destructs without ever being <code>Complete</code>d, either because of an exception, or because the caller decided that initialization failed in an unexceptional way, then the destructor will tell the InitOnce engine that initialization failed. This will unblock any other threads that are waiting for initialization to complete and allow them to give it a try. </p>
<p>If the <code>guard</code> is <code>Complete</code>d, then its destructor tells the InitOnce engine that initialization was successful. </p>
<p>After thinking about all that, you might realize that the fact that you’re throwing C++ exceptions means that you’re already committed to C++, so you may as well go all in: Use <code>std::call_once</code> or C++ static locals. These are part of the C++ standard and are fully exception-aware. Of course, it assumes that all the frames you are throwing across came from the same C++ compiler. </p>


</body>