<body style=max-width:80ch;margin:auto>
<h1 class="entry-title" style="margin-bottom:15px;">Why am I getting an unhandled exception from my C++ function that catches all exceptions?</h1>  <!-- .entry-meta -->

<p>A customer had what they thought was a problem with C++/WinRT coroutines. “We are catching and handling all exceptions, but sometimes our program still crashes with an unhandled exception.”</p>
<pre>winrt::fire_and_forget MyClass::DoSomethingAsync()
{
    auto lifetime = get_strong();
    try {
        auto name = co_await m_user.GetNameAsync();
        m_label.Text(name);
    } catch (...) {
        m_label.Text(L"unknown");
    }
}
</pre>
<p>The C++/WinRT knowledge you need to know here is that a coroutine that returns <code>fire_<wbr/>and_<wbr/>forget</code> terminates the application if an unhandled exception is encountered.</p>
<p>And you can see the unhandled exception in the stack trace:</p>
<pre>KERNELBASE!RaiseFailFastException+0x15c
combase!RoFailFastWithErrorContextInternal2+0x43a
contoso!winrt::terminate+0x28
contoso!std::experimental::coroutine_traits&lt;winrt::fire_and_forget&gt;::promise_type::unhandled_exception+0x9
contoso!`MyClass::DoSomethingAsync$_ResumeCoro$1'::`1'::catch$2+0x1f
VCRUNTIME140_1+0x1080
VCRUNTIME140_1!_NLG_Return2+0x1555
ntdll!RcFrameConsolidation+0x6
contoso!MyClass::DoSomethingAsync$_ResumeCoro$1+0xa9
contoso!std::experimental::coroutine_handle&lt;void&gt;::resume+0x5
contoso!std::experimental::coroutine_handle&lt;void&gt;::operator()+0x5
contoso!winrt::impl::resume_apartment_callback+0x9
...
</pre>
<p>But we did a <code>catch (...)</code>, which catches all exceptions. How did we get an unhandled exception?</p>
<p>The <code>catch (...)</code> catches all exceptions thrown in the preceding <code>try</code> block. But that’s not where the unhandled exception is coming from.</p>
<p>The coroutine was just a red herring. Let’s take coroutines out of the picture and make this a non-coroutine function.</p>
<pre>void MyClass::DoSomething()
{
    try {
        auto name = m_user.GetName();
        m_label.Text(name);
    } catch (...) {
        m_label.Text(L"unknown");
    }
}
</pre>
<p>If an exception occurs in the <code>try</code> block, it is caught and handled by the <code>catch (...)</code> block. But if an exception occurs at the <code>m_label.Text(L"unknown")</code>, <a href="/code/what-happens-if-my-c-exception-handler-itself-raises-an-exception" title="What happens if my C++ exception handler itself raises an exception?"> there’s nobody around to catch the <i>second</i> exception</a>.</p>
<p>You thought you caught the exception, but instead you merely caught <i>an</i> exception. If you don’t want any exceptions to escape your function, you have to play Pokémon and <a href="https://www.youtube.com/watch?v=MpaHR-V_R-o"> catch them all</a>.</p>
<pre>winrt::fire_and_forget MyClass::DoSomethingAsync()
{
    auto lifetime = get_strong();
    try {
        auto name = co_await m_user.GetNameAsync();
        m_label.Text(name);
    } catch (...) {
        <span style="color: #08f;">try {</span>
            m_label.Text(L"unknown");
        <span style="color: #08f;">} catch (...) {
            LOG_CAUGHT_EXCEPTION();
        }</span>
    }
}
</pre>
<p>I’m assuming that if you can’t even set the label to <code>L"unknown"</code> you just want to log the error and proceed anyway. For demonstration purposes, I’m using the <a href="https://github.com/microsoft/wil/wiki/Error-handling-helpers"> WIL error handling helpers</a>.</p>
<p>The nesting here is getting rather annoying, but you can make things a little less awkward by using a function try block.</p>
<pre>winrt::fire_and_forget MyClass::DoSomethingAsync() <span style="color: #08f;">try</span>
{
    auto lifetime = get_strong();
    try {
        auto name = co_await m_user.GetNameAsync();
        m_label.Text(name);
    } catch (...) {
        m_label.Text(L"unknown");
    }
} <span style="color: #08f;">catch (...) {
    // The function is best-effort. Ignore failures.
}</span>
</pre>
<p>The function try lets you specify catch blocks that apply to the entire function body.</p>
<p>Next time, we’ll look at some of the subtle exceptions that can come out of C++/WinRT and XAML.</p>


</body>