<body style=max-width:80ch;margin:auto>
<h1 class="entry-title" style="margin-bottom:15px;">C++ coroutines: What happens if an exception occurs in my return_value?</h1>  <!-- .entry-meta -->

<p>When I introduced <a href="/code/c-coroutines-basic-implementation-of-a-promise-type" title="C++ coroutines: Basic implementation of a promise type"> a basic implementation of a promise type</a>, I noted that the <code>return_value</code> method or <code>return_void</code> method is called when the coroutine performs a <code>co_return</code>. But what happens if the <code>return_value</code> or <code>return_void</code> method raises an exception?</p>
<pre>void return_value(T const&amp; v) const
{
    holder.set_result(v); // what if the copy constructor throws?
}

void unhandled_exception() const noexcept
{
    holder.set_exception(std::current_exception());
}
</pre>
<p>What if we take an exception trying to set the result, say because the copy constructor threw an exception? Do we have to catch the exception and convert it to a <code>holder.set_exception</code>?</p>
<pre>void return_value(T const&amp; v) const
{
    <span style="color: blue;">// Do I have to wrap the set_result?</span>
    <span style="color: blue;">try {</span>
        holder.set_result(v);
    <span style="color: blue;">} catch (...) {</span>
        holder.set_exception(std::current_exception());
    <span style="color: blue;">}</span>
}
</pre>
<p>Let’s go back and look at the transformation that the compiler performs when it generates a coroutine:</p>
<pre>return_type MyCoroutine(args...)
{
    <i>create coroutine state</i>
    <i>copy parameters to coroutine frame</i>
    promise_type p;
    auto return_object = p.get_return_object();

    try {
        co_await p.initial_suspend(); // ¹
        <i>coroutine function body</i>
    } catch (...) {
        p.unhandled_exception();
    }
    co_await p.final_suspend();
    <i>destruct promise p</i>
    <i>destruct parameters in coroutine frame</i>
    <i>destroy coroutine state</i>
}
</pre>
<p>The <code>return_value</code> and <code>return_void</code> happen as part of the transformation of the <code>co_return</code> statement, and that is part of the section marked <i>coroutine function body</i>. Therefore, if an exception occurs during <code>return_value</code> or <code>return_void</code>, it is caught by the <code>catch (...)</code> and is delivered to <code>unhandled_exception</code>.</p>
<p>In other words, the compiler already wrapped your <code>return_value</code> and <code>return_void</code> functions inside a <code>try</code>/<code>catch</code> so you don’t have to.</p>
<p>Note however that there is no <code>try</code>/<code>catch</code> wrapped around the call to <code>unhandled_<wbr/>exception</code>, so that method should be careful not throw any exceptions.</p>
<p>Okay, so that was a brief digression on exceptions that occur when returning a value to the promise. Next time, we’ll look at another improvement to our coroutine promise implementation.</p>


</body>