<body style=max-width:80ch;margin:auto>
<h1 class="entry-title" style="margin-bottom:15px;">Windows Runtime asynchronous operations can fail in two different ways, so make sure you get them both</h1>  <!-- .entry-meta -->

<p>CLR Tasks, PPL tasks, JavaScript Promises, and Windows Runtime asynchronous actions and operations can fail in two ways.</p>
<ul>
<li>They can throw an exception instead of returning the <code>Task</code>, <code>task</code>, <code>IAsyncAction</code>, or <code>IAsyncOperation</code>. “Synchronous failure.”</li>
<li>They can return a <code>Task</code>, <code>task</code>, <code>IAsyncAction</code>, or <code>IAsyncOperation</code> which completes with an exception. “Asynchronous failure.”</li>
</ul>
<p>Synchronous failures are raised at the point you call the method; you can think of them as “immediate failure”. Asynchronous failure are raised at the point you check the result; you can think of them as “delayed failure”.</p>
<table border="1" cellpadding="3" cellspacing="0" class="cp3" style="border-collapse: collapse;">
<tbody>
<tr>
<th>Framework</th>
<th>Synchronous failure</th>
<th>Asynchronous failure</th>
</tr>
<tr>
<td>C#</td>
<td><code>var task = o.DoSomethingAsync()</code></td>
<td><code>task.Result</code><br/>
<code><code>await task</code></code></td>
</tr>
<tr>
<td>PPL</td>
<td><code>auto task = o-&gt;DoSomethingAsync()</code></td>
<td><code>task.get()</code><br/>
<code>co_await task</code></td>
</tr>
<tr>
<td>C++/WinRT</td>
<td><code>auto op = o.DoSomethingAsync()</code></td>
<td><code>op.GetResults()</code><br/>
<code>co_await op</code></td>
</tr>
<tr>
<td>JavaScript</td>
<td><code>var p = o.DoSomethingAsync()</code></td>
<td><code>p.catch()</code><br/>
<code>await p</code></td>
</tr>
</tbody>
</table>
<p>A customer reported that they were getting exceptions from some code, which they couldn’t understand because they thought they were handling exceptions.</p>
<pre>// C++ with PPL
using namespace Concurrency;
using namespace Platform;

task&lt;String^&gt;
Widget::GetNameAsync()
{
    return m_doodad-&gt;GetNameAsync() // crash here
    .then([](task&lt;String^&gt; outerTask) {
        String^ name;

        try {
            name = outerTask.get();
        } catch (...) {
        }

        return name;
    }, task_continuation_context::use_arbitrary());
}
</pre>
<p>The code wraps the <code>outerTask.get()</code> inside a <code>try</code> block, so that should catch all the exceptions that come out of the <code>m_doodad-&gt;GetNameAsync()</code> task.</p>
<p>And that’s true, it does catch all the exceptions that come out of the task.</p>
<p>But the exception that crashed didn’t come out of the task!</p>
<p>The debugger pointed at the line that raised the exception: It was from the call to <code>GetNameAsync()</code> itself, before it even returned a task. The customer got so focused on the Concurrency Runtime that they forgot about the basic rules of C++: If you want to catch an exception, you have to do it inside a <code>try</code> block.</p>
<p>In order to catch that exception, the call to <code>GetNameAsync()</code> must itself be inside a <code>try</code> block.</p>
<pre>task&lt;String^&gt;
Widget::GetNameAsync()
{
    task&lt;String^&gt; nameTask;
    <span style="color: #08f;">try {</span>
        nameTask = m_doodad-&gt;GetNameAsync();
    <span style="color: #08f;">} catch (...) {
        return task_from_result&lt;String^&gt;(nullptr);
    }</span>

    return nameTask.then([](task&lt;String^&gt; outerTask) {
        String^ name;

        try {
            name = outerTask.get();
        } catch (...) {
        }

        return name;
    }, task_continuation_context::use_arbitrary());
}
</pre>
<p>I separated the <code>return m_doodad-&gt;GetNameAsync().then()</code> into two steps:</p>
<pre>    task&lt;String^&gt; nameTask = m_doodad-&gt;GetNameAsync();
    return nameTask.then(...);
</pre>
<p>The <code>try</code> statement inside the <code>then</code> lambda deals with exceptions that come out of the task. We just need another <code>try</code> to deal with the exceptions that occur while trying to produce the task:</p>
<pre>    task&lt;String^&gt; nameTask;
    <span style="color: #08f;">try {</span>
        nameTask = m_doodad-&gt;GetNameAsync();
    <span style="color: #08f;">} catch (...) {
        return task_from_result&lt;String^&gt;(nullptr);
    }</span>
</pre>
<p>If an exception occurs, we catch it and return an already-completed task that produces an empty string. Otherwise, we hook up the continuation that deals with the task completion as before.</p>
<p>Once you see how the expression was taken apart, you can combine them again, putting the entire statement inside a giant <code>try</code> block, even though it’s only the <code>-&gt;GetNameAsync()</code> that we’re interested in. (Most languages with exceptions make it cumbersome to catch exceptions that come out of part of an expression, so most people just expand the scope of the <code>try</code> to include the entire statement.)</p>
<pre>task&lt;String^&gt;
Widget::GetNameAsync()
{
    <span style="color: #08f;">try {</span>
        return m_doodad-&gt;GetNameAsync()
        .then([](task&lt;String^&gt; outerTask) {
            String^ name;

            try {
                name = outerTask.get();
            } catch (...) {
            }

            return name;
        }, task_continuation_context::use_arbitrary());
    <span style="color: #08f;">} catch (...) {
        return task_from_result&lt;String^&gt;(nullptr);
    }</span>
}
</pre>
<p>Note that if the customer had been using PPL with <code>co_await</code> support, the <code>try</code> block would naturally have enclosed both the production of the task as well as handling for its completion: The inability to wrap just part of an expression in a <code>try</code> block actually helps you write correct code this time:</p>
<pre>task&lt;String^&gt;
Widget::GetNameAsync()
{
    try {
        co_return co_await m_doodad-&gt;GetNameAsync();
    } catch (...) {
        co_return nullptr;
    }
}
</pre>
<p>One catch with this rewrite is that <code>co_await</code> of a Concurrency Runtime <code>task</code> does not let you control the task continuation context. It always uses <code>get_current_winrt_context()</code> when awaiting tasks, and <code>CallbackContext::Same</code> when awaiting Windows Runtime asynchronous actions and operations.</p>


</body>